<?xml version="1.0" ?>
<!-- =================================================================================== -->
<!-- |    This document was autogenerated by xacro from kmriiwa.urdf.xacro             | -->
<!-- |    EDITING THIS FILE BY HAND IS NOT RECOMMENDED                                 | -->
<!-- =================================================================================== -->
<robot name="kmriiwa" xmlns:xacro="http://www.ros.org/wiki/xacro">
  <material name="White">
    <color rgba="1.0 1.0 1.0 1.0"/>
  </material>
  <material name="DarkGrey">
    <color rgba="0.3 0.3 0.3 1.0"/>
  </material>

  <!-- Planar joint connecting the robot to the world. -->
  <link name="base_link_0"/>
  <link name="base_link_1"/>
  <joint name="x" type="prismatic">
    <parent link="world"/>
    <child link="base_link_0"/>
    <axis xyz="1 0 0"/>
    <limit>
          <lower>-2</lower>
          <upper>2</upper>
          <effort>80</effort>
          <stiffness>15000</stiffness>
        </limit>
  </joint>
  <joint name="y" type="prismatic">
    <parent link="base_link_0"/>
    <child link="base_link_1"/>
    <axis xyz="0 1 0"/>
    <limit>
          <lower>-2</lower>
          <upper>2</upper>
          <effort>80</effort>
          <stiffness>15000</stiffness>
        </limit>
  </joint>
  <joint name="theta" type="continuous">
    <parent link="base_link_1"/>
    <child link="kmriiwa_base_footprint"/>
    <axis xyz="0 0 1"/>
    <limit>
          <lower>-2</lower>
          <upper>2</upper>
          <effort>80</effort>
          <stiffness>15000</stiffness>
        </limit>
  </joint>
  <transmission name="x_transmission" type="SimpleTransmission">
    <actuator name="x_motor"/>
    <joint name="x"/>
  </transmission>
  <transmission name="y_transmission" type="SimpleTransmission">
    <actuator name="y_motor"/>
    <joint name="y"/>
  </transmission>
  <transmission name="theta_transmission" type="SimpleTransmission">
    <actuator name="theta_motor"/>
    <joint name="theta"/>
  </transmission>

  <!-- distance from wheel-floor contact point to base bottom side-->
  <link name="kmriiwa_base_footprint"/>
  <joint name="kmriiwa_footprint_to_base_link" type="fixed">
    <parent link="kmriiwa_base_footprint"/>
    <child link="kmriiwa_base_link"/>
    <origin rpy="0 0 0.0" xyz="0 0 0.025"/>
  </joint>
  <link name="kmriiwa_base_link">
    <origin rpy="0 0 0" xyz="0 0 0"/>
    <visual>
      <geometry>
        <mesh filename="package://combining_kinematics/models/kmriiwa/meshes/kmp200/KMP200.obj"/>
      </geometry>
      <material name="White"/>
    </visual>
    <collision>
      <!-- <geometry>
        <mesh filename="package://combining_kinematics/models/kmriiwa/meshes/kmp200/KMP200.obj"/>
      </geometry> -->
      <origin rpy="0 0 0" xyz="0.0202 0.0002 0.3336"/>
      <geometry>
        <box size="1.1216 0.6304 0.6672"/>
      </geometry>
    </collision>
    <inertial>
      <origin rpy="0 0 0" xyz="0 0 0.23500000000000001"/>
      <mass value="390"/>
      <!-- obtained from KMP200 model on fusion 360 with some modification to align center of mass with the given one-->
      <inertia ixx="28.95" ixy="0.0" ixz="0.0" iyy="44.03" iyz="0.0" izz="33.83"/>
    </inertial>
  </link>
  <joint name="kmriiwa_base_link_to_top" type="fixed">
    <parent link="kmriiwa_base_link"/>
    <child link="kmriiwa_base_top_link"/>
    <origin rpy="0 0 0.0" xyz="0 0 0.6749999999999999"/>
  </joint>
  <link name="kmriiwa_base_top_link"/>
  <joint name="kmriiwa_laser_B1_joint" type="fixed">
    <parent link="kmriiwa_base_link"/>
    <child link="kmriiwa_laser_B1_link"/>
    <origin rpy="0 0 -0.7854" xyz="0.464 -0.256 0.1168"/>
  </joint>
  <link name="kmriiwa_laser_B1_link">
    <visual>
      <origin rpy="3.1413 0 0" xyz="0 0 0"/>
      <geometry>
        <mesh filename="package://combining_kinematics/models/kmriiwa/meshes/kmp200/sensors/visual/sick_lms1xx.obj"/>
      </geometry>
      <material name="DarkGrey"/>
    </visual>
    <!-- <collision>
      <origin rpy="0 0 0" xyz="0.0 0 0.0"/>
      <geometry>
        <mesh filename="package://combining_kinematics/models/kmriiwa/meshes/kmp200/sensors/collision/sick_lms1xx.obj"/>
      </geometry>
    </collision> -->
    <inertial>
      <mass value="1.2"/>
      <inertia ixx="0.002355" ixy="0.0" ixz="0.0" iyy="0.002355" iyz="0.0" izz="0.0002809"/>
    </inertial>
  </link>
  <joint name="kmriiwa_laser_B4_joint" type="fixed">
    <parent link="kmriiwa_base_link"/>
    <child link="kmriiwa_laser_B4_link"/>
    <origin rpy="0 0 2.3562" xyz="-0.464 0.256 0.1168"/>
  </joint>
  <link name="kmriiwa_laser_B4_link">
    <visual>
      <origin rpy="0 3.1413 3.1413" xyz="0.0 0 0"/>
      <geometry>
        <mesh filename="package://combining_kinematics/models/kmriiwa/meshes/kmp200/sensors/visual/sick_lms1xx.obj"/>
      </geometry>
      <material name="DarkGrey"/>
    </visual>
    <!-- <collision>
      <origin rpy="0 0 0" xyz="0 0 0"/>
      <geometry>
        <mesh filename="package://combining_kinematics/models/kmriiwa/meshes/kmp200/sensors/collision/sick_lms1xx.obj"/>
      </geometry>
    </collision> -->
    <inertial>
      <mass value="1.2"/>
      <inertia ixx="0.002355" ixy="0.0" ixz="0.0" iyy="0.002355" iyz="0.0" izz="0.0002809"/>
    </inertial>
  </link>
  <link name="kmriiwa_front_left_wheel_link">
    <visual>
      <origin rpy="0 0 0" xyz="0 0 0"/>
      <geometry>
        <mesh filename="package://combining_kinematics/models/kmriiwa/meshes/kmp200/wheels/omni_wheel_1.obj" scale="1.06695 1.06695 1.06695"/>
      </geometry>
    </visual>
    <!-- <collision>
      <origin rpy="1.57 0 0" xyz="0 0 0"/>
      <geometry>
        <cylinder length="0.132" radius="0.125"/>
      </geometry>
    </collision> -->
  </link>
  <link name="kmriiwa_front_right_wheel_link">
    <visual>
      <origin rpy="0 0 0" xyz="0 0 0"/>
      <geometry>
        <mesh filename="package://combining_kinematics/models/kmriiwa/meshes/kmp200/wheels/omni_wheel_1.obj" scale="1.06695 1.06695 1.06695"/>
      </geometry>
    </visual>
    <!-- <collision>
      <origin rpy="1.57 0 0" xyz="0 0 0"/>
      <geometry>
        <cylinder length="0.132" radius="0.125"/>
      </geometry>
    </collision> -->
  </link>
  <link name="kmriiwa_back_left_wheel_link">
    <visual>
      <origin rpy="0 0 0" xyz="0 0 0"/>
      <geometry>
        <mesh filename="package://combining_kinematics/models/kmriiwa/meshes/kmp200/wheels/omni_wheel_1.obj" scale="1.06695 1.06695 1.06695"/>
      </geometry>
    </visual>
    <!-- <collision>
      <origin rpy="1.57 0 0" xyz="0 0 0"/>
      <geometry>
        <cylinder length="0.132" radius="0.125"/>
      </geometry>
    </collision> -->
  </link>
  <link name="kmriiwa_back_right_wheel_link">
    <visual>
      <origin rpy="0 0 0" xyz="0 0 0"/>
      <geometry>
        <mesh filename="package://combining_kinematics/models/kmriiwa/meshes/kmp200/wheels/omni_wheel_1.obj" scale="1.06695 1.06695 1.06695"/>
      </geometry>
    </visual>
    <!-- <collision>
      <origin rpy="1.57 0 0" xyz="0 0 0"/>
      <geometry>
        <cylinder length="0.132" radius="0.125"/>
      </geometry>
    </collision> -->
    <!-- <inertial>
            <mass value="14"/>
            <inertia ixx="0.075016" ixy="0.0" ixz="0.0" iyy="0.075016" iyz="0.0" izz="0.109375"/>
        </inertial> -->
  </link>
  <joint name="kmriiwa_front_left_wheel_joint" type="fixed">
    <parent link="kmriiwa_base_link"/>
    <child link="kmriiwa_front_left_wheel_link"/>
    <axis xyz="0 1 0"/>
    <origin xyz="0.28 0.1825 0.1"/>
    <limit effort="100" velocity="100"/>
    <joint_properties damping="0.0" friction="0.0"/>
  </joint>
  <joint name="kmriiwa_front_right_wheel_joint" type="fixed">
    <parent link="kmriiwa_base_link"/>
    <child link="kmriiwa_front_right_wheel_link"/>
    <origin xyz="0.28 -0.1825 0.1"/>
    <axis xyz="0 1 0"/>
    <limit effort="100" velocity="100"/>
    <joint_properties damping="0.0" friction="0.0"/>
  </joint>
  <joint name="kmriiwa_back_left_wheel_joint" type="fixed">
    <parent link="kmriiwa_base_link"/>
    <child link="kmriiwa_back_left_wheel_link"/>
    <origin xyz="-0.28 0.1825 0.1"/>
    <axis xyz="0 1 0"/>
    <limit effort="100" velocity="100"/>
    <joint_properties damping="0.0" friction="0.0"/>
  </joint>
  <joint name="kmriiwa_back_right_wheel_joint" type="fixed">
    <parent link="kmriiwa_base_link"/>
    <child link="kmriiwa_back_right_wheel_link"/>
    <origin xyz="-0.28 -0.1825 0.1"/>
    <axis xyz="0 1 0"/>
    <limit effort="100" velocity="100"/>
    <joint_properties damping="0.0" friction="0.0"/>
  </joint>

  <!-- mount point -->
  <joint name="kmriiwa_mount_point_joint" type="fixed">
    <parent link="kmriiwa_base_top_link"/>
    <child link="kmriiwa_mount_frame"/>
    <origin rpy="0 0 -1.5708" xyz="0.363 -0.184 0"/>
  </joint>
  <link name="kmriiwa_mount_frame" />

</robot>
